2019-09-13 16:30:41,393 - interactiontest - DEBUG - EntityDb(call_john): add_entity(sort=u'number_type', grammar_entry='mobile', name=u'mobile')
2019-09-13 16:30:41,394 - interactiontest - DEBUG - EntityDb(call_john): add_entity returns u'mobile'
2019-09-13 16:30:41,394 - interactiontest - DEBUG - EntityDb(call_john): add_entity(sort=u'number_type', grammar_entry='home', name=u'home')
2019-09-13 16:30:41,394 - interactiontest - DEBUG - EntityDb(call_john): add_entity returns u'home'
2019-09-13 16:30:41,394 - interactiontest - DEBUG - EntityDb(call_john): add_entity(sort=u'contact_name', grammar_entry='mary', name=u'contact_mary')
2019-09-13 16:30:41,394 - interactiontest - DEBUG - EntityDb(call_john): add_entity returns u'contact_mary'
2019-09-13 16:30:41,394 - interactiontest - DEBUG - EntityDb(call_john): add_entity(sort=u'number_type', grammar_entry='work', name=u'work')
2019-09-13 16:30:41,394 - interactiontest - DEBUG - EntityDb(call_john): add_entity returns u'work'
2019-09-13 16:30:41,395 - interactiontest - DEBUG - EntityDb(call_john): add_entity(sort=u'contact_name', grammar_entry='john', name=u'contact_john')
2019-09-13 16:30:41,395 - interactiontest - DEBUG - EntityDb(call_john): add_entity returns u'contact_john'
2019-09-13 16:30:41,395 - interactiontest - DEBUG - Backend()
2019-09-13 16:30:41,595 - interactiontest - ERROR - Encountered an error, sending event 'BACKEND_ERROR'
Traceback (most recent call last):
  File "/opt/local/Library/Frameworks/Python.framework/Versions/2.7/lib/python2.7/site-packages/tdm/backend.py", line 100, in handle_event_from_external_queue
    self._handle_external_event(event)
  File "/opt/local/Library/Frameworks/Python.framework/Versions/2.7/lib/python2.7/site-packages/tdm/backend.py", line 113, in _handle_external_event
    resulting_events = self._send_event_through_components(event)
  File "/opt/local/Library/Frameworks/Python.framework/Versions/2.7/lib/python2.7/site-packages/tdm/backend.py", line 124, in _send_event_through_components
    moves = self._dm.act(events)
  File "/opt/local/Library/Frameworks/Python.framework/Versions/2.7/lib/python2.7/site-packages/tdm/dm/component.py", line 47, in act
    self._act_on_queued_events()
  File "/opt/local/Library/Frameworks/Python.framework/Versions/2.7/lib/python2.7/site-packages/tdm/dm/component.py", line 86, in _act_on_queued_events
    self._handle_event(event)
  File "/opt/local/Library/Frameworks/Python.framework/Versions/2.7/lib/python2.7/site-packages/tdm/dm/component.py", line 101, in _handle_event
    self.forward_event_internally_and_externally(event)
  File "/opt/local/Library/Frameworks/Python.framework/Versions/2.7/lib/python2.7/site-packages/tdm/dm/component.py", line 104, in forward_event_internally_and_externally
    self._event_dispatcher.dispatch(event)
  File "/opt/local/Library/Frameworks/Python.framework/Versions/2.7/lib/python2.7/site-packages/tdm/event_dispatcher.py", line 27, in dispatch
    self._send_event_to_subscribing_modules(event)
  File "/opt/local/Library/Frameworks/Python.framework/Versions/2.7/lib/python2.7/site-packages/tdm/event_dispatcher.py", line 49, in _send_event_to_subscribing_modules
    handler, event.get_type(), event)
  File "/opt/local/Library/Frameworks/Python.framework/Versions/2.7/lib/python2.7/site-packages/tdm/event_dispatcher.py", line 55, in _send_to_subscribing_module
    module.process_event(protected_event)
  File "/opt/local/Library/Frameworks/Python.framework/Versions/2.7/lib/python2.7/site-packages/tdm/lib/module.py", line 50, in process_event
    handler()
  File "/opt/local/Library/Frameworks/Python.framework/Versions/2.7/lib/python2.7/site-packages/tdm/dm/dme_module.py", line 56, in _handle_interpretation
    self._set_input_event_and_run_update_and_select()
  File "/opt/local/Library/Frameworks/Python.framework/Versions/2.7/lib/python2.7/site-packages/tdm/dm/dme_module.py", line 61, in _set_input_event_and_run_update_and_select
    self.run_update_and_set_ddd_when_needed()
  File "/opt/local/Library/Frameworks/Python.framework/Versions/2.7/lib/python2.7/site-packages/tdm/dm/dme_module.py", line 66, in run_update_and_set_ddd_when_needed
    self.run_update()
  File "/opt/local/Library/Frameworks/Python.framework/Versions/2.7/lib/python2.7/site-packages/tdm/dm/dme_module.py", line 131, in run_update
    self.update_module.run(self._tis)
  File "tdm/dm/update.py", line 167, in tdm.dm.update.UpdateModule.run (tdm/dm/update.c:11076)
  File "/opt/local/Library/Frameworks/Python.framework/Versions/2.7/lib/python2.7/site-packages/tdm/dm/isu_module.py", line 128, in repeatGroupSequence
    if self._apply(ruleGroup, identifier, tis):
  File "/opt/local/Library/Frameworks/Python.framework/Versions/2.7/lib/python2.7/site-packages/tdm/dm/isu_module.py", line 139, in _apply
    if self.applyRule(rule, tis):
  File "/opt/local/Library/Frameworks/Python.framework/Versions/2.7/lib/python2.7/site-packages/tdm/dm/isu_module.py", line 102, in applyRule
    rule.applyEffects(self._ddd_manager)
  File "/opt/local/Library/Frameworks/Python.framework/Versions/2.7/lib/python2.7/site-packages/tdm/dm/isu_rule.py", line 26, in applyEffects
    apply(self.effects, arguments)
  File "tdm/dm/update.py", line 2057, in tdm.dm.update.exec_dev_perform.effects (tdm/dm/update.c:96732)
  File "/opt/local/Library/Frameworks/Python.framework/Versions/2.7/lib/python2.7/site-packages/tdm/ddd/service_interface.py", line 40, in get_action
    % (self._actions.keys(), name))
UnexpectedActionException: Expected one of the known actions [] but got 'MakeCall'
